<?xml version="1.0" encoding="UTF-8"?>
<testng-results ignored="0" total="4" passed="2" failed="2" skipped="0">
  <reporter-output>
  </reporter-output>
  <suite started-at="2024-08-29T00:44:53 IST" name="Default suite" finished-at="2024-08-29T00:44:56 IST" duration-ms="3168">
    <groups>
    </groups>
    <test started-at="2024-08-29T00:44:53 IST" name="Default test" finished-at="2024-08-29T00:44:56 IST" duration-ms="3168">
      <class name="api.test.UserTest2">
        <test-method is-config="true" signature="setUp()[pri:0, instance:api.test.UserTest2@2b40ff9c]" started-at="2024-08-29T00:44:53 IST" name="setUp" finished-at="2024-08-29T00:44:54 IST" duration-ms="849" status="PASS">
          <reporter-output>
          </reporter-output>
        </test-method> <!-- setUp -->
        <test-method signature="testPostUser()[pri:1, instance:api.test.UserTest2@2b40ff9c]" started-at="2024-08-29T00:44:54 IST" name="testPostUser" description="Create User" finished-at="2024-08-29T00:44:56 IST" duration-ms="1774" status="PASS">
          <reporter-output>
          </reporter-output>
        </test-method> <!-- testPostUser -->
        <test-method signature="testGetUserByName()[pri:2, instance:api.test.UserTest2@2b40ff9c]" started-at="2024-08-29T00:44:56 IST" name="testGetUserByName" description="Get User By Name" finished-at="2024-08-29T00:44:56 IST" duration-ms="173" status="FAIL">
          <exception class="java.lang.AssertionError">
            <message>
              <![CDATA[expected [200] but found [404]]]>
            </message>
            <full-stacktrace>
              <![CDATA[java.lang.AssertionError: expected [200] but found [404]
at org.testng.Assert.fail(Assert.java:111)
at org.testng.Assert.failNotEquals(Assert.java:1578)
at org.testng.Assert.assertEqualsImpl(Assert.java:150)
at org.testng.Assert.assertEquals(Assert.java:132)
at org.testng.Assert.assertEquals(Assert.java:1419)
at org.testng.Assert.assertEquals(Assert.java:1383)
at org.testng.Assert.assertEquals(Assert.java:1429)
at api.test.UserTest2.testGetUserByName(UserTest2.java:80)
at java.base/jdk.internal.reflect.DirectMethodHandleAccessor.invoke(DirectMethodHandleAccessor.java:103)
at java.base/java.lang.reflect.Method.invoke(Method.java:580)
at org.testng.internal.invokers.MethodInvocationHelper.invokeMethod(MethodInvocationHelper.java:141)
at org.testng.internal.invokers.TestInvoker.invokeMethod(TestInvoker.java:686)
at org.testng.internal.invokers.TestInvoker.invokeTestMethod(TestInvoker.java:230)
at org.testng.internal.invokers.MethodRunner.runInSequence(MethodRunner.java:63)
at org.testng.internal.invokers.TestInvoker$MethodInvocationAgent.invoke(TestInvoker.java:992)
at org.testng.internal.invokers.TestInvoker.invokeTestMethods(TestInvoker.java:203)
at org.testng.internal.invokers.TestMethodWorker.invokeTestMethods(TestMethodWorker.java:154)
at org.testng.internal.invokers.TestMethodWorker.run(TestMethodWorker.java:134)
at java.base/java.util.ArrayList.forEach(ArrayList.java:1597)
at org.testng.TestRunner.privateRun(TestRunner.java:739)
at org.testng.TestRunner.run(TestRunner.java:614)
at org.testng.SuiteRunner.runTest(SuiteRunner.java:421)
at org.testng.SuiteRunner.runSequentially(SuiteRunner.java:413)
at org.testng.SuiteRunner.privateRun(SuiteRunner.java:373)
at org.testng.SuiteRunner.run(SuiteRunner.java:312)
at org.testng.SuiteRunnerWorker.runSuite(SuiteRunnerWorker.java:52)
at org.testng.SuiteRunnerWorker.run(SuiteRunnerWorker.java:95)
at org.testng.TestNG.runSuitesSequentially(TestNG.java:1274)
at org.testng.TestNG.runSuitesLocally(TestNG.java:1208)
at org.testng.TestNG.runSuites(TestNG.java:1112)
at org.testng.TestNG.run(TestNG.java:1079)
at org.testng.remote.AbstractRemoteTestNG.run(AbstractRemoteTestNG.java:115)
at org.testng.remote.RemoteTestNG.initAndRun(RemoteTestNG.java:293)
at org.testng.remote.RemoteTestNG.main(RemoteTestNG.java:91)
]]>
            </full-stacktrace>
          </exception> <!-- java.lang.AssertionError -->
          <reporter-output>
          </reporter-output>
        </test-method> <!-- testGetUserByName -->
        <test-method signature="testUpdateUserByName()[pri:3, instance:api.test.UserTest2@2b40ff9c]" started-at="2024-08-29T00:44:56 IST" name="testUpdateUserByName" description="Update User By Name" finished-at="2024-08-29T00:44:56 IST" duration-ms="157" status="PASS">
          <reporter-output>
          </reporter-output>
        </test-method> <!-- testUpdateUserByName -->
        <test-method signature="testDeleteUserName()[pri:4, instance:api.test.UserTest2@2b40ff9c]" started-at="2024-08-29T00:44:56 IST" name="testDeleteUserName" description="Delete User By Name" finished-at="2024-08-29T00:44:56 IST" duration-ms="163" status="FAIL">
          <exception class="java.lang.AssertionError">
            <message>
              <![CDATA[expected [200] but found [404]]]>
            </message>
            <full-stacktrace>
              <![CDATA[java.lang.AssertionError: expected [200] but found [404]
at org.testng.Assert.fail(Assert.java:111)
at org.testng.Assert.failNotEquals(Assert.java:1578)
at org.testng.Assert.assertEqualsImpl(Assert.java:150)
at org.testng.Assert.assertEquals(Assert.java:132)
at org.testng.Assert.assertEquals(Assert.java:1419)
at org.testng.Assert.assertEquals(Assert.java:1383)
at org.testng.Assert.assertEquals(Assert.java:1429)
at api.test.UserTest2.testDeleteUserName(UserTest2.java:104)
at java.base/jdk.internal.reflect.DirectMethodHandleAccessor.invoke(DirectMethodHandleAccessor.java:103)
at java.base/java.lang.reflect.Method.invoke(Method.java:580)
at org.testng.internal.invokers.MethodInvocationHelper.invokeMethod(MethodInvocationHelper.java:141)
at org.testng.internal.invokers.TestInvoker.invokeMethod(TestInvoker.java:686)
at org.testng.internal.invokers.TestInvoker.invokeTestMethod(TestInvoker.java:230)
at org.testng.internal.invokers.MethodRunner.runInSequence(MethodRunner.java:63)
at org.testng.internal.invokers.TestInvoker$MethodInvocationAgent.invoke(TestInvoker.java:992)
at org.testng.internal.invokers.TestInvoker.invokeTestMethods(TestInvoker.java:203)
at org.testng.internal.invokers.TestMethodWorker.invokeTestMethods(TestMethodWorker.java:154)
at org.testng.internal.invokers.TestMethodWorker.run(TestMethodWorker.java:134)
at java.base/java.util.ArrayList.forEach(ArrayList.java:1597)
at org.testng.TestRunner.privateRun(TestRunner.java:739)
at org.testng.TestRunner.run(TestRunner.java:614)
at org.testng.SuiteRunner.runTest(SuiteRunner.java:421)
at org.testng.SuiteRunner.runSequentially(SuiteRunner.java:413)
at org.testng.SuiteRunner.privateRun(SuiteRunner.java:373)
at org.testng.SuiteRunner.run(SuiteRunner.java:312)
at org.testng.SuiteRunnerWorker.runSuite(SuiteRunnerWorker.java:52)
at org.testng.SuiteRunnerWorker.run(SuiteRunnerWorker.java:95)
at org.testng.TestNG.runSuitesSequentially(TestNG.java:1274)
at org.testng.TestNG.runSuitesLocally(TestNG.java:1208)
at org.testng.TestNG.runSuites(TestNG.java:1112)
at org.testng.TestNG.run(TestNG.java:1079)
at org.testng.remote.AbstractRemoteTestNG.run(AbstractRemoteTestNG.java:115)
at org.testng.remote.RemoteTestNG.initAndRun(RemoteTestNG.java:293)
at org.testng.remote.RemoteTestNG.main(RemoteTestNG.java:91)
]]>
            </full-stacktrace>
          </exception> <!-- java.lang.AssertionError -->
          <reporter-output>
          </reporter-output>
        </test-method> <!-- testDeleteUserName -->
      </class> <!-- api.test.UserTest2 -->
    </test> <!-- Default test -->
  </suite> <!-- Default suite -->
</testng-results>
